Workbook

Sheet 사용법
A1: 이 통합 문서 사용법
A3: 1. '기록' 시트에서 각 시험(T-001~T-014)의 회차별로 결과를 직접 입력합니다.
A4: - D열(결과): PASS / FAIL / 조건부 PASS / 미실시 중 드롭다운으로 선택
A5: - E열(측정값/오차): 예) '오차 0.8cm', '90.4도(목표 90도)', '인식 3/3프레임'
A6: - F열(실패 원인 카테고리): FAIL일 때만 드롭다운에서 선택 (없으면 '기타' 선택 후 G열에 서술)
A7: - G열(실패 원인 상세): 반드시 구체적으로 서술 (예: 'AMCL 초기 위치 오차 누적으로 costmap 상 벽 오검출, ABORTED 3회')
A8: - 노란색 셀만 입력하면 됩니다. 나머지는 자동 계산/참조됩니다.
A10: 2. '요약' 시트는 '기록' 시트를 기반으로 자동 집계됩니다 (수식 있음, 직접 입력 금지).
A11: - 시험별 성공/실패 개수, 성공률, 판정(합격/조건부 합격/불합격)이 자동으로 갱신됩니다.
A12: - 판정 기준: 전량 PASS=합격, 80% 이상 PASS=조건부 합격, 미만=불합격 (필요시 임계값 조정 가능)
A13: - 실패 원인 카테고리별 발생 건수도 하단에 자동 집계됩니다.
A15: 3. '시험항목 상세' 시트는 각 시험이 driving_waypoint_node.py의 어느 함수/모듈과
... A19: 추가/삭제해 탄력적으로 조정할 수 있습니다 (요약 시트 수식은 COUNTIFS 기반이라 자동 반영됨).

Sheet 요약
A1: YEYU 자율주행 사전검증 로봇 — 최종 시연 전 시험 결과 요약
A2: 작성일: 2026-08-18 / 시험 장소: yeyu 자체 제작 미니 테스트 코스(실내) / 시험 담당: 강유나, 김예은
A4: 시험 ID | B4: 시험 내용 | C4: 목표(인수 기준) | D4: 반복 횟수 | E4: 성공(PASS) | F4: 실패(FAIL) | G4: 성공률 | H4: 판정
A5: T-001 | B5: 크랭크 코스 주행 | C5: 오차 1cm 이하 | D5: 10 | E5: =COUNTIFS(기록!$A:$A,A5,기록!$D:$D,"PASS") -> 4 | F5: =COUNTIFS(기록!$A:$A,A5,기록!$D:$D,"FAIL") -> 6 | G5: =IFERROR(E5/D5,0) -> 0.4 | H5: =IF(COUNTIFS(기록!$A:$A,A5)=0,"미실시",IF(E5=D5,"합격",IF(E5/D5>=0.8,"조건부 합격","불합격"))) -> 불합격
A6: T-002 | B6: S 코스 주행 | C6: 각도 오차 최소화 | D6: 10 | E6: =COUNTIFS(기록!$A:$A,A6,기록!$D:$D,"PASS") -> 7 | F6: =COUNTIFS(기록!$A:$A,A6,기록!$D:$D,"FAIL") -> 3 | G6: =IFERROR(E6/D6,0) -> 0.7 | H6: =IF(COUNTIFS(기록!$A:$A,A6)=0,"미실시",IF(E6=D6,"합격",IF(E6/D6>=0.8,"조건부 합격","불합격"))) -> 불합격
A7: T-003 | B7: 목표 경유점 도착 | C7: 위치 오차 3cm 이내 | D7: 10 | E7: =COUNTIFS(기록!$A:$A,A7,기록!$D:$D,"PASS") -> 8 | F7: =COUNTIFS(기록!$A:$A,A7,기록!$D:$D,"FAIL") -> 2 | G7: =IFERROR(E7/D7,0) -> 0.8 | H7: =IF(COUNTIFS(기록!$A:$A,A7)=0,"미실시",IF(E7=D7,"합격",IF(E7/D7>=0.8,"조건부 합격","불합격"))) -> 조건부 합격
A8: T-004 | B8: 좁은 통로 통과 | C8: 충돌 없이 통과 | D8: 5 | E8: =COUNTIFS(기록!$A:$A,A8,기록!$D:$D,"PASS") -> 4 | F8: =COUNTIFS(기록!$A:$A,A8,기록!$D:$D,"FAIL") -> 1 | G8: =IFERROR(E8/D8,0) -> 0.8 | H8: =IF(COUNTIFS(기록!$A:$A,A8)=0,"미실시",IF(E8=D8,"합격",IF(E8/D8>=0.8,"조건부 합격","불합격"))) -> 조건부 합격
A9: T-005 | B9: 신호등 인식 확인 | C9: 오검출 없이 초록 신호 3프레임 연속 인식 후 재출발 | D9: 5 | E9: =COUNTIFS(기록!$A:$A,A9,기록!$D:$D,"PASS") -> 3 | F9: =COUNTIFS(기록!$A:$A,A9,기록!$D:$D,"FAIL") -> 2 | G9: =IFERROR(E9/D9,0) -> 0.6 | H9: =IF(COUNTIFS(기록!$A:$A,A9)=0,"미실시",IF(E9=D9,"합격",IF(E9/D9>=0.8,"조건부 합격","불합격"))) -> 불합격
A10: T-006 | B10: 가속 확인 | C10: 표지판 인식 후 가속, 규정속도(0.18m/s) 이상 유지 | D10: 5 | E10: =COUNTIFS(기록!$A:$A,A10,기록!$D:$D,"PASS") -> 4 | F10: =COUNTIFS(기록!$A:$A,A10,기록!$D:$D,"FAIL") -> 1 | G10: =IFERROR(E10/D10,0) -> 0.8 | H10: =IF(COUNTIFS(기록!$A:$A,A10)=0,"미실시",IF(E10=D10,"합격",IF(E10/D10>=0.8,"조건부 합격","불합격"))) -> 조건부 합격
A11: T-007 | B11: 장애물 감지 | C11: 정지 성공률 100% | D11: 10 | E11: =COUNTIFS(기록!$A:$A,A11,기록!$D:$D,"PASS") -> 10 | F11: =COUNTIFS(기록!$A:$A,A11,기록!$D:$D,"FAIL") -> 0 | G11: =IFERROR(E11/D11,0) -> 1 | H11: =IF(COUNTIFS(기록!$A:$A,A11)=0,"미실시",IF(E11=D11,"합격",IF(E11/D11>=0.8,"조건부 합격","불합격"))) -> 합격
A12: T-008 | B12: ArUco 마커 인식 | C12: 인식 성공률 기록 | D12: 10 | E12: =COUNTIFS(기록!$A:$A,A12,기록!$D:$D,"PASS") -> 8 | F12: =COUNTIFS(기록!$A:$A,A12,기록!$D:$D,"FAIL") -> 2 | G12: =IFERROR(E12/D12,0) -> 0.8 | H12: =IF(COUNTIFS(기록!$A:$A,A12)=0,"미실시",IF(E12=D12,"합격",IF(E12/D12>=0.8,"조건부 합격","불합격"))) -> 조건부 합격
A13: T-009 | B13: 충전 위치 파킹 | C13: 성공률과 오차 기록 | D13: 10 | E13: =COUNTIFS(기록!$A:$A,A13,기록!$D:$D,"PASS") -> 7 | F13: =COUNTIFS(기록!$A:$A,A13,기록!$D:$D,"FAIL") -> 2 | G13: =IFERROR(E13/D13,0) -> 0.7 | H13: =IF(COUNTIFS(기록!$A:$A,A13)=0,"미실시",IF(E13=D13,"합격",IF(E13/D13>=0.8,"조건부 합격","불합격"))) -> 불합격
A14: T-010 | B14: 재시험 주행 | C14: 지정 재시험 경로로 정상 재이동 및 재판정 성공률 | D14: 10 | E14: =COUNTIFS(기록!$A:$A,A14,기록!$D:$D,"PASS") -> 9 | F14: =COUNTIFS(기록!$A:$A,A14,기록!$D:$D,"FAIL") -> 1 | G14: =IFERROR(E14/D14,0) -> 0.9 | H14: =IF(COUNTIFS(기록!$A:$A,A14)=0,"미실시",IF(E14=D14,"합격",IF(E14/D14>=0.8,"조건부 합격","불합격"))) -> 조건부 합격
A15: T-011 | B15: Wi-Fi 연결 해제 | C15: 정의된 안전 동작 수행 | D15: 5 | E15: =COUNTIFS(기록!$A:$A,A15,기록!$D:$D,"PASS") -> 4 | F15: =COUNTIFS(기록!$A:$A,A15,기록!$D:$D,"FAIL") -> 1 | G15: =IFERROR(E15/D15,0) -> 0.8 | H15: =IF(COUNTIFS(기록!$A:$A,A15)=0,"미실시",IF(E15=D15,"합격",IF(E15/D15>=0.8,"조건부 합격","불합격"))) -> 조건부 합격
A16: T-012 | B16: 노드 비정상 종료 | C16: 자동 재시작 확인 | D16: 5 | E16: =COUNTIFS(기록!$A:$A,A16,기록!$D:$D,"PASS") -> 4 | F16: =COUNTIFS(기록!$A:$A,A16,기록!$D:$D,"FAIL") -> 1 | G16: =IFERROR(E16/D16,0) -> 0.8 | H16: =IF(COUNTIFS(기록!$A:$A,A16)=0,"미실시",IF(E16=D16,"합격",IF(E16/D16>=0.8,"조건부 합격","불합격"))) -> 조건부 합격
... A18: T-014 | B18: 전체 서비스 시나리오 | C18: 성공률 기록 | D18: 10 | E18: =COUNTIFS(기록!$A:$A,A18,기록!$D:$D,"PASS") -> 7 | F18: =COUNTIFS(기록!$A:$A,A18,기록!$D:$D,"FAIL") -> 3 | G18: =IFERROR(E18/D18,0) -> 0.7 | H18: =IF(COUNTIFS(기록!$A:$A,A18)=0,"미실시",IF(E18=D18,"합격",IF(E18/D18>=0.8,"조건부 합격","불합격"))) -> 불합격
A19: 전체 | D19: =SUM(D5:D18) -> 110 | E19: =SUM(E5:E18) -> 83 | F19: =SUM(F5:F18) -> 26 | G19: =IFERROR(E19/D19,0) -> 0.75454545
A21: 실패 원인 카테고리별 집계 (기록 시트 기준)
A22: 실패 원인 카테고리 | B22: 발생 건수
A23: 라인(IR) 이탈/오검출 | B23: =COUNTIF(기록!$F:$F,A23) -> 7
A24: 카메라 인식 실패(HSV/ArUco) | B24: =COUNTIF(기록!$F:$F,A24) -> 3
A25: Nav2 경로탐색 실패(ABORTED) | B25: =COUNTIF(기록!$F:$F,A25) -> 0
A26: AMCL/TF 불안정 | B26: =COUNTIF(기록!$F:$F,A26) -> 3
A27: 장애물 오감지/미감지 | B27: =COUNTIF(기록!$F:$F,A27) -> 0
A28: 통신(Wi-Fi/Serial) 문제 | B28: =COUNTIF(기록!$F:$F,A28) -> 2
A29: 정렬/오차 기준 초과 | B29: =COUNTIF(기록!$F:$F,A29) -> 6
A30: 타임아웃(제한시간 초과) | B30: =COUNTIF(기록!$F:$F,A30) -> 4
A31: 하드웨어(모터/센서) 이상 | B31: =COUNTIF(기록!$F:$F,A31) -> 0
A32: 소프트웨어 예외/버그 | B32: =COUNTIF(기록!$F:$F,A32) -> 2
A33: 기타 | B33: =COUNTIF(기록!$F:$F,A33) -> 0

Sheet 기록
A1: 시험 ID | B1: 시험 내용 | C1: 회차 | D1: 결과(PASS/FAIL) | E1: 측정값/오차 | F1: 실패 원인 카테고리 | G1: 실패 원인 상세 | H1: 관련 코드/모듈 | I1: 시험 일시 | J1: 담당자 | K1: 비고
A2: T-001 | B2: 크랭크 코스 주행 | C2: 1 | D2: FAIL | E2: 종료 지점 오차 1.8cm (목표 1cm 이하) | F2: 라인(IR) 이탈/오검출 | G2: 크랭크 회전(TURNING) 구간에서 IR 라인 재진입 각도가 어긋나 직진 복귀 시 오차 누적, cost_scaling_factor 조정 전 | H2: crank_control_loop / _handle_crank_following / _handle_crank_creeping / _handle_crank_turning / _on_crank_done | I2: 2026-08-13 10:10 | J2: 강유나
A3: T-001 | B3: 크랭크 코스 주행 | C3: 2 | D3: FAIL | E3: 출발 시 라인 벗어남 | F3: 라인(IR) 이탈/오검출 | G3: 회전 완료 후 직진 복귀 구간에서 라인 재검출 지연으로 오차 누적, PID 게인 1차 조정 중 | H3: crank_control_loop / _handle_crank_following / _handle_crank_creeping / _handle_crank_turning / _on_crank_done | I3: 2026-08-13 10:45 | J3: 강유나
A4: T-001 | B4: 크랭크 코스 주행 | C4: 3 | D4: FAIL | E4: 출발 시 라인 벗어남 | F4: 라인(IR) 이탈/오검출 | G4: 크랭크 회전(TURNING) 구간에서 IR 라인 재진입 각도가 어긋남 | H4: crank_control_loop / _handle_crank_following / _handle_crank_creeping / _handle_crank_turning / _on_crank_done | I4: 2026-08-14 09:40 | J4: 강유나
A5: T-001 | B5: 크랭크 코스 주행 | C5: 4 | D5: FAIL | E5: 출발 시 라인 벗어남 | F5: 라인(IR) 이탈/오검출 | G5: 크랭크 회전(TURNING) 구간에서 IR 라인 재진입 각도가 어긋남 | H5: crank_control_loop / _handle_crank_following / _handle_crank_creeping / _handle_crank_turning / _on_crank_done | I5: 2026-08-14 09:56 | J5: 강유나
A6: T-001 | B6: 크랭크 코스 주행 | C6: 5 | D6: FAIL | E6: 출발 시 라인 벗어남 | F6: 라인(IR) 이탈/오검출 | G6: 크랭크 회전(TURNING) 구간에서 IR 라인 재진입 각도가 어긋남 | H6: crank_control_loop / _handle_crank_following / _handle_crank_creeping / _handle_crank_turning / _on_crank_done | I6: 2026-08-15 11:00 | J6: 강유나
A7: T-001 | B7: 크랭크 코스 주행 | C7: 6 | D7: FAIL | E7: 출발 시 라인 벗어남 | F7: 라인(IR) 이탈/오검출 | G7: 크랭크 회전(TURNING) 구간에서 IR 라인 재진입 각도가 어긋남 | H7: crank_control_loop / _handle_crank_following / _handle_crank_creeping / _handle_crank_turning / _on_crank_done | I7: 2026-08-15 11:42 | J7: 강유나
A8: T-001 | B8: 크랭크 코스 주행 | C8: 7 | D8: PASS | E8: 종료 지점 도착 다음 구간 인식 완료 | H8: crank_control_loop / _handle_crank_following / _handle_crank_creeping / _handle_crank_turning / _on_crank_done | I8: 2026-08-16 09:00 | J8: 강유나
A9: T-001 | B9: 크랭크 코스 주행 | C9: 8 | D9: PASS | E9: 종료 지점 도착 다음 구간 인식 완료 | H9: crank_control_loop / _handle_crank_following / _handle_crank_creeping / _handle_crank_turning / _on_crank_done | I9: 2026-08-16 09:37 | J9: 강유나
A10: T-001 | B10: 크랭크 코스 주행 | C10: 9 | D10: PASS | E10: 종료 지점 도착 다음 구간 인식 완료 | H10: crank_control_loop / _handle_crank_following / _handle_crank_creeping / _handle_crank_turning / _on_crank_done | I10: 2026-08-17 09:10 | J10: 강유나
A11: T-001 | B11: 크랭크 코스 주행 | C11: 10 | D11: PASS | E11: 종료 지점 도착 다음 구간 인식 완료 | H11: crank_control_loop / _handle_crank_following / _handle_crank_creeping / _handle_crank_turning / _on_crank_done | I11: 2026-08-17 09:25 | J11: 강유나
A12: T-002 | B12: S 코스 주행 | C12: 1 | D12: FAIL | E12: 도착 지점 거리오차 42cm (기준 30cm 이내) | F12: 정렬/오차 기준 초과 | G12: 라인을 벗어남 offset 값이 오른쪽으로 치우침 | H12: s_course_control_loop / _detect_s_line_offset / _on_s_course_done (PID 조향, S_ANGULAR_GAIN) | I12: 2026-08-13 14:00 | J12: 강유나
A13: T-002 | B13: S 코스 주행 | C13: 2 | D13: FAIL | E13: 도착 지점 거리오차 40cm(기준 30cm 이내) | F13: 정렬/오차 기준 초과 | G13: 라인을 벗어남 offset 값이 오른쪽으로 치우침 | H13: s_course_control_loop / _detect_s_line_offset / _on_s_course_done (PID 조향, S_ANGULAR_GAIN) | I13: 2026-08-13 14:17 | J13: 강유나
A14: T-002 | B14: S 코스 주행 | C14: 3 | D14: FAIL | E14: 도착 지점 거리오차 60cm(기준 30cm 이내) | F14: 정렬/오차 기준 초과 | G14: S자 후반 곡선 후 다음 구간도착판정 지점을 지나침 | H14: s_course_control_loop / _detect_s_line_offset / _on_s_course_done (PID 조향, S_ANGULAR_GAIN) | I14: 2026-08-14 15:50 | J14: 강유나
A15: T-002 | B15: S 코스 주행 | C15: 4 | D15: PASS | E15: 도착 지점 거리오차 17cm(기준 30cm 이내), 진행각 오차 0.6도 | H15: s_course_control_loop / _detect_s_line_offset / _on_s_course_done (PID 조향, S_ANGULAR_GAIN) | I15: 2026-08-14 16:03 | J15: 강유나
A16: T-002 | B16: S 코스 주행 | C16: 5 | D16: PASS | E16: 도착 지점 거리오차 11cm(기준 30cm 이내), 진행각 오차 1.3도 | H16: s_course_control_loop / _detect_s_line_offset / _on_s_course_done (PID 조향, S_ANGULAR_GAIN) | I16: 2026-08-15 13:10 | J16: 강유나
A17: T-002 | B17: S 코스 주행 | C17: 6 | D17: PASS | E17: 도착 지점 거리오차 17cm(기준 30cm 이내), 진행각 오차 2.4도 | H17: s_course_control_loop / _detect_s_line_offset / _on_s_course_done (PID 조향, S_ANGULAR_GAIN) | I17: 2026-08-15 13:22 | J17: 강유나
A18: T-002 | B18: S 코스 주행 | C18: 7 | D18: PASS | E18: 도착 지점 거리오차 16cm(기준 30cm 이내), 진행각 오차 1.4도 | H18: s_course_control_loop / _detect_s_line_offset / _on_s_course_done (PID 조향, S_ANGULAR_GAIN) | I18: 2026-08-16 13:20 | J18: 강유나
A19: T-002 | B19: S 코스 주행 | C19: 8 | D19: PASS | E19: 도착 지점 거리오차 10cm(기준 30cm 이내), 진행각 오차 1.5도 | H19: s_course_control_loop / _detect_s_line_offset / _on_s_course_done (PID 조향, S_ANGULAR_GAIN) | I19: 2026-08-16 13:56 | J19: 강유나
A20: T-002 | B20: S 코스 주행 | C20: 9 | D20: PASS | E20: 도착 지점 거리오차 22cm(기준 30cm 이내), 진행각 오차 1.5도 | H20: s_course_control_loop / _detect_s_line_offset / _on_s_course_done (PID 조향, S_ANGULAR_GAIN) | I20: 2026-08-17 15:00 | J20: 강유나
A21: T-002 | B21: S 코스 주행 | C21: 10 | D21: PASS | E21: 도착 지점 거리오차 12cm(기준 30cm 이내), 진행각 오차 0.8도 | H21: s_course_control_loop / _detect_s_line_offset / _on_s_course_done (PID 조향, S_ANGULAR_GAIN) | I21: 2026-08-17 15:29 | J21: 강유나
A22: T-003 | B22: 목표 경유점 도착 | C22: 1 | D22: FAIL | E22: 위치 오차 4.6cm (목표 3cm 이내) | F22: AMCL/TF 불안정 | G22: AMCL 초기 위치 추정 수렴 전 도착판정이 발생하여 오차 초과 | H22: _check_crank_arrival / _check_s_course_arrival / on_nav_result 도착판정 | I22: 2026-07-27 11:10 | J22: 김예은
A23: T-003 | B23: 목표 경유점 도착 | C23: 2 | D23: FAIL | E23: 위치 오차 3.8cm (목표 3cm 이내) | F23: AMCL/TF 불안정 | G23: TF 지연으로 도착판정 시점의 실제 위치와 계산 위치 간 편차 발생 | H23: _check_crank_arrival / _check_s_course_arrival / on_nav_result 도착판정 | I23: 2026-07-27 11:26 | J23: 김예은
A24: T-003 | B24: 목표 경유점 도착 | C24: 3 | D24: PASS | E24: 위치 오차 2.2cm (목표 3cm 이내) | H24: _check_crank_arrival / _check_s_course_arrival / on_nav_result 도착판정 | I24: 2026-07-27 11:48 | J24: 김예은
A25: T-003 | B25: 목표 경유점 도착 | C25: 4 | D25: PASS | E25: 위치 오차 2.2cm (목표 3cm 이내) | H25: _check_crank_arrival / _check_s_course_arrival / on_nav_result 도착판정 | I25: 2026-07-27 12:21 | J25: 김예은
A26: T-003 | B26: 목표 경유점 도착 | C26: 5 | D26: PASS | E26: 위치 오차 1.6cm (목표 3cm 이내) | H26: _check_crank_arrival / _check_s_course_arrival / on_nav_result 도착판정 | I26: 2026-07-27 12:37 | J26: 김예은
A27: T-003 | B27: 목표 경유점 도착 | C27: 6 | D27: PASS | E27: 위치 오차 2.1cm (목표 3cm 이내) | H27: _check_crank_arrival / _check_s_course_arrival / on_nav_result 도착판정 | I27: 2026-07-27 13:22 | J27: 김예은
A28: T-003 | B28: 목표 경유점 도착 | C28: 7 | D28: PASS | E28: 위치 오차 1.7cm (목표 3cm 이내) | H28: _check_crank_arrival / _check_s_course_arrival / on_nav_result 도착판정 | I28: 2026-07-27 13:36 | J28: 김예은
A29: T-003 | B29: 목표 경유점 도착 | C29: 8 | D29: PASS | E29: 위치 오차 1.0cm (목표 3cm 이내) | H29: _check_crank_arrival / _check_s_course_arrival / on_nav_result 도착판정 | I29: 2026-07-27 13:49 | J29: 김예은
A30: T-003 | B30: 목표 경유점 도착 | C30: 9 | D30: PASS | E30: 위치 오차 2.7cm (목표 3cm 이내) | H30: _check_crank_arrival / _check_s_course_arrival / on_nav_result 도착판정 | I30: 2026-07-27 14:12 | J30: 김예은
A31: T-003 | B31: 목표 경유점 도착 | C31: 10 | D31: PASS | E31: 위치 오차 1.3cm (목표 3cm 이내) | H31: _check_crank_arrival / _check_s_course_arrival / on_nav_result 도착판정 | I31: 2026-07-27 14:53 | J31: 김예은
A32: T-004 | B32: 좁은 통로 통과 | C32: 1 | D32: FAIL | E32: 좌측 벽면 접촉(여유폭 -0.5cm) | F32: AMCL/TF 불안정 | G32: costmap inflation_radius 기본값 상태에서 통로 폭 대비 팽창 영역 과다, 튜닝 전 시험 | H32: set_inflation_radius_pair / costmap inflation_radius 파라미터 | I32: 2026-07-28 10:20 | J32: 김예은
A33: T-004 | B33: 좁은 통로 통과 | C33: 2 | D33: PASS | E33: 충돌 없이 통과, 최소 여유폭 3.2cm | H33: set_inflation_radius_pair / costmap inflation_radius 파라미터 | I33: 2026-07-28 10:59 | J33: 김예은
A34: T-004 | B34: 좁은 통로 통과 | C34: 3 | D34: PASS | E34: 충돌 없이 통과, 최소 여유폭 3.8cm | H34: set_inflation_radius_pair / costmap inflation_radius 파라미터 | I34: 2026-07-28 11:38 | J34: 김예은
A35: T-004 | B35: 좁은 통로 통과 | C35: 4 | D35: PASS | E35: 충돌 없이 통과, 최소 여유폭 3.4cm | H35: set_inflation_radius_pair / costmap inflation_radius 파라미터 | I35: 2026-07-28 12:11 | J35: 김예은
A36: T-004 | B36: 좁은 통로 통과 | C36: 5 | D36: PASS | E36: 충돌 없이 통과, 최소 여유폭 2.2cm | H36: set_inflation_radius_pair / costmap inflation_radius 파라미터 | I36: 2026-07-28 12:40 | J36: 김예은
A37: T-005 | B37: 신호등 인식 확인 | C37: 1 | D37: FAIL | E37: 5.6s 경과 후에도 초록 3프레임 미인식 | F37: 타임아웃(제한시간 초과) | G37: GREEN_LOWER/HIGHER HSV 임계값이 좁게 설정되어 조명 변화 시 인식 지연 발생 | H37: _process_signal / detect_signal_color(GREEN_LOWER/HIGHER) / _after_signal_wait_result | I37: 2026-07-30 09:50 | J37: 김예은
A38: T-005 | B38: 신호등 인식 확인 | C38: 2 | D38: FAIL | E38: 5.2s 경과 후에도 초록 3프레임 미인식 | F38: 타임아웃(제한시간 초과) | G38: GREEN_LOWER/HIGHER HSV 임계값이 좁게 설정되어 조명 변화 시 인식 지연 발생 | H38: _process_signal / detect_signal_color(GREEN_LOWER/HIGHER) / _after_signal_wait_result | I38: 2026-07-30 10:15 | J38: 김예은
A39: T-005 | B39: 신호등 인식 확인 | C39: 3 | D39: PASS | E39: 초록 신호 3/3프레임 연속 인식, 재출발까지 1.4s (5s 이내) | H39: _process_signal / detect_signal_color(GREEN_LOWER/HIGHER) / _after_signal_wait_result | I39: 2026-07-30 10:30 | J39: 김예은
A40: T-005 | B40: 신호등 인식 확인 | C40: 4 | D40: PASS | E40: 초록 신호 3/3프레임 연속 인식, 재출발까지 3.4s (5s 이내) | H40: _process_signal / detect_signal_color(GREEN_LOWER/HIGHER) / _after_signal_wait_result | I40: 2026-07-30 10:59 | J40: 김예은
...

Sheet 시험항목 상세
A1: 시험 ID | B1: 시험 내용 | C1: 반복 횟수 | D1: 목표(인수 기준) | E1: 주요 관련 코드/모듈 (driving_waypoint_node.py) | F1: 관련 UR(요구사항ID)
A2: T-001 | B2: 크랭크 코스 주행 | C2: 10 | D2: 오차 1cm 이하 | E2: crank_control_loop / _handle_crank_following / _handle_crank_creeping / _handle_crank_turning / _on_crank_done | F2: UR-003
A3: T-002 | B3: S 코스 주행 | C3: 10 | D3: 각도 오차 최소화 | E3: s_course_control_loop / _detect_s_line_offset / _on_s_course_done (PID 조향, S_ANGULAR_GAIN) | F3: UR-004
A4: T-003 | B4: 목표 경유점 도착 | C4: 10 | D4: 위치 오차 3cm 이내 | E4: _check_crank_arrival / _check_s_course_arrival / on_nav_result 도착판정 | F4: UR-002
A5: T-004 | B5: 좁은 통로 통과 | C5: 5 | D5: 충돌 없이 통과 | E5: set_inflation_radius_pair / costmap inflation_radius 파라미터 | F5: UR-002
A6: T-005 | B6: 신호등 인식 확인 | C6: 5 | D6: 오검출 없이 초록 신호 3프레임 연속 인식 후 재출발 | E6: _process_signal / detect_signal_color(GREEN_LOWER/HIGHER) / _after_signal_wait_result | F6: UR-005
A7: T-006 | B7: 가속 확인 | C7: 5 | D7: 표지판 인식 후 가속, 규정속도(0.18m/s) 이상 유지 | E7: _process_speed_sign / detect_speed_sign(BLUE_LOWER/HIGHER) / accel_zone_check_loop | F7: UR-006
A8: T-007 | B8: 장애물 감지 | C8: 10 | D8: 정지 성공률 100% | E8: on_obstacle_distance(OBSTACLE_STOP_DISTANCE_CM) / _start_obstacle_response | F8: UR-008
A9: T-008 | B9: ArUco 마커 인식 | C9: 10 | D9: 인식 성공률 기록 | E9: _process_aruco / _select_marker_index / _make_observation | F9: UR-007
A10: T-009 | B10: 충전 위치 파킹 | C10: 10 | D10: 성공률과 오차 기록 | E10: parking_control_loop / _handle_parking_* / _on_parking_done | F10: UR-007
A11: T-010 | B11: 재시험 주행 | C11: 10 | D11: 지정 재시험 경로로 정상 재이동 및 재판정 성공률 | E11: on_start_retry_request / RETRY_ENTRY / _finish_retry / _announce_retry_result | F11: UR-011
A12: T-011 | B12: Wi-Fi 연결 해제 | C12: 5 | D12: 정의된 안전 동작 수행 | E12: wifi_polling_loop / check_wifi_status / on_wifi_disconnected | F12: UR-013
A13: T-012 | B13: 노드 비정상 종료 | C13: 5 | D13: 자동 재시작 확인 | E13: PM2/launch 프로세스 관리 (노드 외부 영역, driving_node 자체 로직 아님) | F13: UR-009
... A15: T-014 | B15: 전체 서비스 시나리오 | C15: 10 | D15: 성공률 기록 | E15: DrivingNode 전체 상태머신 (NAV_ARRIVAL_TRANSITIONS, stage_results, _announce_final_result) | F15: UR-001~UR-014 (전체)
