Workbook

Sheet WBS_계획
A1: TurtleBot3 ROS2 면허시험 코스 주행 로봇(팀 yeyu) WBS
A4: 프로젝트 범위: TurtleBot3 Burger 기반 안내·순찰·정밀 파킹·안전 대응 서비스 | 기간: 2026-07-20 ~ 2026-08-14
A6: WBS ID | B6: 대분류 | C6: 중분류 | D6: 작업 패키지 | E6: 주요 산출물 | F6: 담당자 | G6: 시작일 | H6: 종료일 | I6: 기간(일) | J6: 선행 작업 | K6: 우선순위 | L6: 상태 | M6: 진척률 | N6: 완료 기준 | O6: 비고
A7: A.1 | B7: 프로젝트 관리 | C7: 요구사항 | D7: 서비스 시나리오 정의 | E7: 요구사항 명세서 | F7: 공동 | G7: 46223 | H7: 46223 | I7: 1 | K7: 높음 | L7: 완료 | M7: 1 | N7: 각 구간 요구사항 ID·검증방법 등록
A8: A.2 | B8: 프로젝트 관리 | C8: 협업 | D8: GitHub 전략 구성(세그먼트 기반 브랜치 정책) | E8: 협업 환경/브랜치 규칙 | F8: 강유나 | G8: 46232 | H8: 46232 | I8: 1 | K8: 높음 | L8: 완료 | M8: 1 | N8: 브랜치 규칙 확정, 팀원 공유 완료
A9: A.3 | B9: 프로젝트 관리 | C9: 관리 | D9: Notion 일자별 진행사항 로깅 체계 | E9: Notion 로그 DB | F9: 공동 | G9: 46223 | H9: 46254 | I9: 2 | J9: A.2 | K9: 중간 | L9: 진행중 | M9: 0.5 | N9: 세션마다 로그 누락 없이 기록
A10: A.4 | B10: 프로젝트 관리 | C10: 일정 | D10: 4주 일정·마일스톤 관리 | E10: 마일스톤 문서 | F10: 공동 | G10: 46240 | H10: 46240 | I10: 1 | J10: A.1 | K10: 중간 | L10: 완료 | M10: 1 | N10: 주차별 마일스톤 문서화
A11: A.5 | B11: 프로젝트 관리 | C11: 위험 | D11: 위험 관리 대장 작성·운영 | E11: 위험 관리 대장 | F11: 김예은 | G11: 46251 | H11: 46251 | I11: 1 | J11: A.1 | K11: 중간 | L11: 미착수 | M11: 0 | N11: 위험 항목 등록, 주 1회 이상 갱신
A12: A.6 | B12: 프로젝트 관리 | C12: 변경 | D12: 변경 관리 대장 작성·운영 | E12: 변경 관리 대장 | F12: 김예은 | G12: 46251 | H12: 46251 | I12: 1 | J12: A.1 | K12: 중간 | L12: 미착수 | M12: 0 | N12: 요구사항/코드 변경 시 영향도 기록
A13: B.1 | B13: 로봇 시스템 | C13: 개발환경 | D13: ROS2 작업공간·yeyu_* 패키지 구성 | E13: colcon 작업공간 | F13: 강유나 | G13: 46224 | H13: 46224 | I13: 1 | K13: 높음 | L13: 완료 | M13: 1 | N13: colcon build 정상
A14: B.2 | B14: 로봇 시스템 | C14: Bringup | D14: TurtleBot3 Bringup 검증 | E14: Bringup 실행 로그 | F14: 김예은 | G14: 46223 | H14: 46223 | I14: 1 | J14: B.1 | K14: 높음 | L14: 완료 | M14: 1 | N14: 모터·odom·scan 토픽 정상
A15: B.3 | B15: 로봇 시스템 | C15: 하드웨어 | D15: 아두이노 시리얼 브리지(IR 3소자+LED) | E15: arduino_sensor_bridge_serial 노드 | F15: 강유나 | G15: 46237 | H15: 46238 | I15: 2 | J15: B.1 | K15: 높음 | L15: 완료 | M15: 1 | N15: ir_l/c/r_state, rgb_cmd 정상 송수신
A16: B.4 | B16: 로봇 시스템 | C16: 보정 | D16: 오도메트리 직진·회전 보정 | E16: 보정 파라미터/CSV | F16: 공동 | G16: 46241 | H16: 46245 | I16: 5 | J16: B.2 | K16: 높음 | L16: 완료 | M16: 1 | N16: 파라미터 수정, 수정 전후 비교 | O16: 실측 CSV 존재(precision_test_results)
A17: B.5 | B17: 로봇 시스템 | C17: 로그 | D17: 로그 저장 구조 구성(rosbag·CSV 규칙) | E17: 로그 디렉터리 규칙 문서 | F17: 김예은 | G17: 46251 | H17: 46251 | I17: 1 | J17: B.1 | K17: 중간 | L17: 미착수 | M17: 0 | N17: 임무별 로그 자동 생성 규칙 문서화
A18: C.1 | B18: 지도·자율주행 | C18: 계획 | D18: 지도 작성 계획 | E18: 지도 작성 계획서 | F18: 공동 | G18: 46239 | H18: 46239 | I18: 1 | K18: 중간 | L18: 완료 | M18: 1 | N18: 대상 코스 전체 범위, SLAM 주행 경로, 필요 장비(로봇/원격PC) 확정
A19: C.2 | B19: 지도·자율주행 | C19: SLAM | D19: SLAM 지도 생성 및 GIMP 수정 | E19: map.pgm/yaml | F19: 강유나 | G19: 46223 | H19: 46234 | I19: 11 | J19: C.1 | K19: 높음 | L19: 완료 | M19: 1 | N19: 코스 전체 커버리지, .pgm/.yaml 저장
A20: C.3 | B20: 지도·자율주행 | C20: Localization | D20: Navigation2 설정 및 AMCL Localization 검증 | E20: nav2/amcl 설정 | F20: 김예은 | G20: 46223 | H20: 46225 | I20: 3 | J20: C.2 | K20: 높음 | L20: 완료 | M20: 1 | N20: 초기 위치 추정 오차 기준 이내, 반복 재현성 확인 및 단일 목표점 이동 성공
A21: C.4 | B21: 지도·자율주행 | C21: 경유점 | D21: 경유점 작성 | E21: waypoint 파일 | F21: 공동 | G21: 46229 | H21: 46232 | I21: 3 | J21: C.3 | K21: 높음 | L21: 완료 | M21: 1 | N21: 신규 wp 좌표·yaw 검증
A22: C.5 | B22: 지도·자율주행 | C22: Nav2 | D22: Nav2 구현 | E22: Nav2 액션 클라이언트 로직 | F22: 김예은 | G22: 46230 | H22: 46238 | I22: 9 | J22: C.4 | K22: 높음 | L22: 완료 | M22: 1 | N22: 전체 웨이포인트 시퀀스 정상 동작
A23: C.6 | B23: 지도·자율주행 | C23: 튜닝 | D23: Nav2 파라미터 설정·튜닝 | E23: nav2_params.yaml | F23: 김예은 | G23: 46230 | H23: 46238 | I23: 9 | J23: C.5 | K23: 높음 | L23: 완료 | M23: 1 | N23: 단일 목표점 이동 5회 성공
A24: C.7 | B24: 지도·자율주행 | C24: 크랭크 | D24: (크랭크) IR+카메라 융합 조향 로직 | E24: 크랭크 트래킹 로직 | F24: 강유나 | G24: 46239 | H24: 46244 | I24: 6 | J24: C.6 | K24: 높음 | L24: 완료 | M24: 1 | N24: 크랭크 코스 진입~완주 정상 동작
A25: C.8 | B25: 지도·자율주행 | C25: S자 | D25: (S자) 시각 제어 알고리즘 | E25: S자 트래킹 로직 | F25: 강유나 | G25: 46239 | H25: 46243 | I25: 5 | J25: C.6 | K25: 높음 | L25: 완료 | M25: 1 | N25: S자 코스 진입~완주 정상 동작
A26: C.9 | B26: 지도·자율주행 | C26: 신호등 | D26: (신호등) SIGNAL_WAIT 판정 | E26: signal 판정 로직 | F26: 김예은 | G26: 46230 | H26: 46232 | I26: 3 | J26: C.6 | K26: 높음 | L26: 완료 | M26: 1 | N26: 초록 3프레임 인식 PASS / 5초 초과 FAIL, 재출발 정상 동작
A27: C.10 | B27: 지도·자율주행 | C27: 가속구간 | D27: (가속구간) ACCEL_ZONE 판정 및 속도 제어 | E27: accel 판정 로직 | F27: 김예은 | G27: 46230 | H27: 46232 | I27: 3 | J27: C.9 | K27: 높음 | L27: 완료 | M27: 1 | N27: 규정 속도 0.5초 이상 유지 시 PASS, Nav2 파라미터 동적 변경 정상 동작
A28: C.11 | B28: 지도·자율주행 | C28: 주차 | D28: (아루코 주차) 주차 상태머신 및 판정 | E28: 주차 상태머신 | F28: 강유나 | G28: 46230 | H28: 46233 | I28: 4 | J28: C.6 | K28: 높음 | L28: 완료 | M28: 1 | N28: 정렬 오차(좌우/거리) 기준 이내 PASS, 재시도 3회 소진 시 FAIL
A29: C.12 | B29: 지도·자율주행 | C29: 안전 | D29: 장애물 대응 파라미터 설정 | E29: 안전 파라미터 세트 | F29: 김예은 | G29: 46244 | H29: 46245 | I29: 2 | J29: C.6 | K29: 높음 | L29: 완료 | M29: 1 | N29: 정적 장애물 10회 회피
A30: C.13 | B30: 지도·자율주행 | C30: 복구 | D30: 복구 동작(Recovery) 설정 | E30: 복구 동작 설정 | F30: 김예은 | G30: 46244 | H30: 46245 | I30: 2 | J30: C.12 | K30: 높음 | L30: 완료 | M30: 1 | N30: 막힘·목표 실패 시 복구 동작 수행
... A49: E.7 | B49: 서비스 기능 | C49: 파킹상태 | D49: Aruco 파킹 상태 | E49: 파킹 상태 로직 | F49: 강유나 | G49: 46230 | H49: 46233 | I49: 4 | J49: C.11 | K49: 높음 | L49: 완료 | M49: 1 | N49: wp9 도착 시 ArUco 탐색 상태로 정상 전환, 정렬 완료 판정 및 PASS 확정, 다음 지점 이동
A50: E.9 | B50: 서비스 기능 | C50: 이상감지 | D50: 이상 감지 (장애물, 구간별 FAIL 판정, E_STOP) | E50: 이상 감지 로직 | F50: 김예은 | G50: ? | H50: ? | I50: 3 | J50: E.1 | K50: 높음 | L50: ? | M50: 1 | N50: 구간별 FAIL 사유(reason) 포함 기록, 경로탐색 3회 실패 시 E_STOP 진입 및 장애물 확인 시 LED 3회 깜빡이고 정지
A51: E.10 | B51: 서비스 기능 | C51: 복귀 | D51: 복귀 상태 (RESULT_SUMMARY/wp11 복귀) | E51: 복귀 상태 로직 | F51: 김예은 | G51: ? | H51: ? | I51: 2 | J51: E.7 | K51: 중간 | L51: ? | M51: 1 | N51: 전 구간 완주 후 wp11 복귀, 결과 요약 발행·TTS 안내
A52: E.11 | B52: 서비스 기능 | C52: 관리자명령 | D52: 관리자 명령 처리 (재시험/비상정지 서비스) | E52: 관리자 명령 서비스 | F52: 김예은 | G52: 46244 | H52: 46244 | I52: 1 | J52: E.1 | K52: 중간 | L52: 완료 | M52: 1 | N52: /start_retry, /emergency_stop 서비스 정상 동작
A53: F.1 | B53: 시스템 통합 | C53: Launch | D53: 전체 Launch 파일 통합 | E53: 통합 launch 파일 | F53: 공동 | J53: D.12;E.1 | K53: 높음 | L53: 미착수 | M53: 0 | N53: bringup·camera·nav2·driving_node·audio·arduino_bridge 통합 실행
A54: F.2 | B54: 시스템 통합 | C54: 자동실행 | D54: 전원 인가 자동 실행 | E54: 자동 실행 설정 | F54: 김예은 | J54: F.1 | K54: 중간 | L54: 미착수 | M54: 0 | N54: 부팅 시 필요 노드 자동 기동
A55: F.3 | B55: 시스템 통합 | C55: 실행순서 | D55: 노드 실행 순서 관리 | E55: 실행 순서 관리 설정 | F55: 강유나 | J55: F.1 | K55: 높음 | L55: 미착수 | M55: 0 | N55: 의존 순서(카메라→Nav2→driving_node 등) 보장
A56: F.4 | B56: 시스템 통합 | C56: 재시작 | D56: 노드 자동 재시작 | E56: 재시작 설정 | F56: 김예은 | J56: F.3 | K56: 높음 | L56: 미착수 | M56: 0 | N56: turtlebot3_ros 등 크래시 시 자동 복구
A57: F.5 | B57: 시스템 통합 | C57: 통신안전 | D57: Wi-Fi 단절 대응 | E57: Wi-Fi 단절 대응 로직 | F57: 강유나 | G57: 46246 | H57: 46246 | I57: 1 | J57: F.1 | K57: 높음 | L57: 미착수 | M57: 0 | N57: 통신 두절 시 안전 정지, 재연결 시 복귀
A58: F.6 | B58: 시스템 통합 | C58: Watchdog | D58: Watchdog 구성 | E58: Watchdog 설정 | F58: 강유나 | J58: F.4 | K58: 높음 | L58: 미착수 | M58: 0 | N58: 노드 응답 없음 감지 및 알림
A59: F.7 | B59: 시스템 통합 | C59: 성능최적화 | D59: CPU와 메모리 최적화 | E59: 성능 최적화 설정 | F59: 김예은 | J59: F.1 | K59: 중간 | L59: 미착수 | M59: 0 | N59: vcgencmd 기준 스로틀링 미발생, 부하 기준 이내
A60: F.8 | B60: 시스템 통합 | C60: 통신최적화 | D60: 토픽 주기 최적화 | E60: 통신 최적화 설정 | F60: 김예은 | J60: F.7 | K60: 중간 | L60: 미착수 | M60: 0 | N60: RTPS_READER_HISTORY 등 경고 최소화
A61: F.9 | B61: 시스템 통합 | C61: 파라미터통합 | D61: 최종 파라미터 통합 | E61: 최종 파라미터 세트 | F61: 공동 | G61: 46246 | H61: 46246 | I61: 1 | J61: F.8 | K61: 높음 | L61: 완료 | M61: 1 | N61: 전 구간 파라미터(threshold, 속도 등) 최종본 확정·문서화
...

Sheet Gantt_4주
A1: TurtleBot3 ROS 2 WBS — 4주 간트 차트
A4: WBS ID | B4: 작업 패키지 | C4: 담당자 | D4: 상태 | E4: 1주차 | J4: 2주차 | O4: 3주차 | T4: 4주차 | Y4: 5주차
E5: 46223 | F5: 46224 | G5: 46225 | H5: 46226 | I5: 46227 | J5: 46230 | K5: 46231 | L5: 46232 | M5: 46233 | N5: 46234 | O5: 46237 | P5: 46238 | Q5: 46239 | R5: 46240 | S5: 46241 | T5: 46244 | U5: 46245 | V5: 46246 | W5: 46247 | X5: 46248 | Y5: 46251 | Z5: 46252 | AA5: 46253 | AB5: 46254 | AC5: 46255
A6: A.1 | B6: 서비스 시나리오·요구사항 정의 | C6: =VLOOKUP($A6,WBS_계획!$A:$O,6,FALSE) -> 공동 | D6: =VLOOKUP($A6,WBS_계획!$A:$O,12,FALSE) -> 완료 | E6: =IF(AND(E$5>=VLOOKUP($A6,WBS_계획!$A:$O,7,FALSE()),E$5<=VLOOKUP($A6,WBS_계획!$A:$O,8,FALSE())),"■","") -> ■ | F6: =IF(AND(F$5>=VLOOKUP($A6,WBS_계획!$A:$O,7,FALSE()),F$5<=VLOOKUP($A6,WBS_계획!$A:$O,8,FALSE())),"■","") | G6: =IF(AND(G$5>=VLOOKUP($A6,WBS_계획!$A:$O,7,FALSE()),G$5<=VLOOKUP($A6,WBS_계획!$A:$O,8,FALSE())),"■","") | H6: =IF(AND(H$5>=VLOOKUP($A6,WBS_계획!$A:$O,7,FALSE()),H$5<=VLOOKUP($A6,WBS_계획!$A:$O,8,FALSE())),"■","") | I6: =IF(AND(I$5>=VLOOKUP($A6,WBS_계획!$A:$O,7,FALSE()),I$5<=VLOOKUP($A6,WBS_계획!$A:$O,8,FALSE())),"■","") | J6: =IF(AND(J$5>=VLOOKUP($A6,WBS_계획!$A:$O,7,FALSE()),J$5<=VLOOKUP($A6,WBS_계획!$A:$O,8,FALSE())),"■","") | K6: =IF(AND(K$5>=VLOOKUP($A6,WBS_계획!$A:$O,7,FALSE()),K$5<=VLOOKUP($A6,WBS_계획!$A:$O,8,FALSE())),"■","") | L6: =IF(AND(L$5>=VLOOKUP($A6,WBS_계획!$A:$O,7,FALSE()),L$5<=VLOOKUP($A6,WBS_계획!$A:$O,8,FALSE())),"■","") | ... AC6: =IF(AND(AC$5>=VLOOKUP($A6,WBS_계획!$A:$O,7,FALSE()),AC$5<=VLOOKUP($A6,WBS_계획!$A:$O,8,FALSE())),"■","")
A7: B.2 | B7: TurtleBot3 Bringup 검증 | C7: =VLOOKUP($A7,WBS_계획!$A:$O,6,FALSE) -> 김예은 | D7: =VLOOKUP($A7,WBS_계획!$A:$O,12,FALSE) -> 완료 | E7: =IF(AND(E$5>=VLOOKUP($A7,WBS_계획!$A:$O,7,FALSE()),E$5<=VLOOKUP($A7,WBS_계획!$A:$O,8,FALSE())),"■","") -> ■ | F7: =IF(AND(F$5>=VLOOKUP($A7,WBS_계획!$A:$O,7,FALSE()),F$5<=VLOOKUP($A7,WBS_계획!$A:$O,8,FALSE())),"■","") | G7: =IF(AND(G$5>=VLOOKUP($A7,WBS_계획!$A:$O,7,FALSE()),G$5<=VLOOKUP($A7,WBS_계획!$A:$O,8,FALSE())),"■","") | H7: =IF(AND(H$5>=VLOOKUP($A7,WBS_계획!$A:$O,7,FALSE()),H$5<=VLOOKUP($A7,WBS_계획!$A:$O,8,FALSE())),"■","") | I7: =IF(AND(I$5>=VLOOKUP($A7,WBS_계획!$A:$O,7,FALSE()),I$5<=VLOOKUP($A7,WBS_계획!$A:$O,8,FALSE())),"■","") | J7: =IF(AND(J$5>=VLOOKUP($A7,WBS_계획!$A:$O,7,FALSE()),J$5<=VLOOKUP($A7,WBS_계획!$A:$O,8,FALSE())),"■","") | K7: =IF(AND(K$5>=VLOOKUP($A7,WBS_계획!$A:$O,7,FALSE()),K$5<=VLOOKUP($A7,WBS_계획!$A:$O,8,FALSE())),"■","") | L7: =IF(AND(L$5>=VLOOKUP($A7,WBS_계획!$A:$O,7,FALSE()),L$5<=VLOOKUP($A7,WBS_계획!$A:$O,8,FALSE())),"■","") | ... AC7: =IF(AND(AC$5>=VLOOKUP($A7,WBS_계획!$A:$O,7,FALSE()),AC$5<=VLOOKUP($A7,WBS_계획!$A:$O,8,FALSE())),"■","")
A8: C.3 | B8: Navigation2 설정 및 AMCL Localization 검증 | C8: =VLOOKUP($A8,WBS_계획!$A:$O,6,FALSE) -> 김예은 | D8: =VLOOKUP($A8,WBS_계획!$A:$O,12,FALSE) -> 완료 | E8: =IF(AND(E$5>=VLOOKUP($A8,WBS_계획!$A:$O,7,FALSE()),E$5<=VLOOKUP($A8,WBS_계획!$A:$O,8,FALSE())),"■","") -> ■ | F8: =IF(AND(F$5>=VLOOKUP($A8,WBS_계획!$A:$O,7,FALSE()),F$5<=VLOOKUP($A8,WBS_계획!$A:$O,8,FALSE())),"■","") -> ■ | G8: =IF(AND(G$5>=VLOOKUP($A8,WBS_계획!$A:$O,7,FALSE()),G$5<=VLOOKUP($A8,WBS_계획!$A:$O,8,FALSE())),"■","") -> ■ | H8: =IF(AND(H$5>=VLOOKUP($A8,WBS_계획!$A:$O,7,FALSE()),H$5<=VLOOKUP($A8,WBS_계획!$A:$O,8,FALSE())),"■","") | I8: =IF(AND(I$5>=VLOOKUP($A8,WBS_계획!$A:$O,7,FALSE()),I$5<=VLOOKUP($A8,WBS_계획!$A:$O,8,FALSE())),"■","") | J8: =IF(AND(J$5>=VLOOKUP($A8,WBS_계획!$A:$O,7,FALSE()),J$5<=VLOOKUP($A8,WBS_계획!$A:$O,8,FALSE())),"■","") | K8: =IF(AND(K$5>=VLOOKUP($A8,WBS_계획!$A:$O,7,FALSE()),K$5<=VLOOKUP($A8,WBS_계획!$A:$O,8,FALSE())),"■","") | L8: =IF(AND(L$5>=VLOOKUP($A8,WBS_계획!$A:$O,7,FALSE()),L$5<=VLOOKUP($A8,WBS_계획!$A:$O,8,FALSE())),"■","") | ... AC8: =IF(AND(AC$5>=VLOOKUP($A8,WBS_계획!$A:$O,7,FALSE()),AC$5<=VLOOKUP($A8,WBS_계획!$A:$O,8,FALSE())),"■","")
A9: C.2 | B9: SLAM 지도 생성 및 GIMP 수정 | C9: =VLOOKUP($A9,WBS_계획!$A:$O,6,FALSE) -> 강유나 | D9: =VLOOKUP($A9,WBS_계획!$A:$O,12,FALSE) -> 완료 | E9: =IF(AND(E$5>=VLOOKUP($A9,WBS_계획!$A:$O,7,FALSE()),E$5<=VLOOKUP($A9,WBS_계획!$A:$O,8,FALSE())),"■","") -> ■ | F9: =IF(AND(F$5>=VLOOKUP($A9,WBS_계획!$A:$O,7,FALSE()),F$5<=VLOOKUP($A9,WBS_계획!$A:$O,8,FALSE())),"■","") -> ■ | G9: =IF(AND(G$5>=VLOOKUP($A9,WBS_계획!$A:$O,7,FALSE()),G$5<=VLOOKUP($A9,WBS_계획!$A:$O,8,FALSE())),"■","") -> ■ | H9: =IF(AND(H$5>=VLOOKUP($A9,WBS_계획!$A:$O,7,FALSE()),H$5<=VLOOKUP($A9,WBS_계획!$A:$O,8,FALSE())),"■","") -> ■ | I9: =IF(AND(I$5>=VLOOKUP($A9,WBS_계획!$A:$O,7,FALSE()),I$5<=VLOOKUP($A9,WBS_계획!$A:$O,8,FALSE())),"■","") -> ■ | J9: =IF(AND(J$5>=VLOOKUP($A9,WBS_계획!$A:$O,7,FALSE()),J$5<=VLOOKUP($A9,WBS_계획!$A:$O,8,FALSE())),"■","") -> ■ | K9: =IF(AND(K$5>=VLOOKUP($A9,WBS_계획!$A:$O,7,FALSE()),K$5<=VLOOKUP($A9,WBS_계획!$A:$O,8,FALSE())),"■","") -> ■ | L9: =IF(AND(L$5>=VLOOKUP($A9,WBS_계획!$A:$O,7,FALSE()),L$5<=VLOOKUP($A9,WBS_계획!$A:$O,8,FALSE())),"■","") -> ■ | ... AC9: =IF(AND(AC$5>=VLOOKUP($A9,WBS_계획!$A:$O,7,FALSE()),AC$5<=VLOOKUP($A9,WBS_계획!$A:$O,8,FALSE())),"■","")
A10: B.1 | B10: ROS2 작업공간·yeyu_* 패키지 구성 | C10: =VLOOKUP($A10,WBS_계획!$A:$O,6,FALSE) -> 강유나 | D10: =VLOOKUP($A10,WBS_계획!$A:$O,12,FALSE) -> 완료 | E10: =IF(AND(E$5>=VLOOKUP($A10,WBS_계획!$A:$O,7,FALSE()),E$5<=VLOOKUP($A10,WBS_계획!$A:$O,8,FALSE())),"■","") | F10: =IF(AND(F$5>=VLOOKUP($A10,WBS_계획!$A:$O,7,FALSE()),F$5<=VLOOKUP($A10,WBS_계획!$A:$O,8,FALSE())),"■","") -> ■ | G10: =IF(AND(G$5>=VLOOKUP($A10,WBS_계획!$A:$O,7,FALSE()),G$5<=VLOOKUP($A10,WBS_계획!$A:$O,8,FALSE())),"■","") | H10: =IF(AND(H$5>=VLOOKUP($A10,WBS_계획!$A:$O,7,FALSE()),H$5<=VLOOKUP($A10,WBS_계획!$A:$O,8,FALSE())),"■","") | I10: =IF(AND(I$5>=VLOOKUP($A10,WBS_계획!$A:$O,7,FALSE()),I$5<=VLOOKUP($A10,WBS_계획!$A:$O,8,FALSE())),"■","") | J10: =IF(AND(J$5>=VLOOKUP($A10,WBS_계획!$A:$O,7,FALSE()),J$5<=VLOOKUP($A10,WBS_계획!$A:$O,8,FALSE())),"■","") | K10: =IF(AND(K$5>=VLOOKUP($A10,WBS_계획!$A:$O,7,FALSE()),K$5<=VLOOKUP($A10,WBS_계획!$A:$O,8,FALSE())),"■","") | L10: =IF(AND(L$5>=VLOOKUP($A10,WBS_계획!$A:$O,7,FALSE()),L$5<=VLOOKUP($A10,WBS_계획!$A:$O,8,FALSE())),"■","") | ... AC10: =IF(AND(AC$5>=VLOOKUP($A10,WBS_계획!$A:$O,7,FALSE()),AC$5<=VLOOKUP($A10,WBS_계획!$A:$O,8,FALSE())),"■","")
A11: D.5 | B11: 카메라 기본 구동 | C11: =VLOOKUP($A11,WBS_계획!$A:$O,6,FALSE) -> 공동 | D11: =VLOOKUP($A11,WBS_계획!$A:$O,12,FALSE) -> 완료 | E11: =IF(AND(E$5>=VLOOKUP($A11,WBS_계획!$A:$O,7,FALSE()),E$5<=VLOOKUP($A11,WBS_계획!$A:$O,8,FALSE())),"■","") | F11: =IF(AND(F$5>=VLOOKUP($A11,WBS_계획!$A:$O,7,FALSE()),F$5<=VLOOKUP($A11,WBS_계획!$A:$O,8,FALSE())),"■","") | G11: =IF(AND(G$5>=VLOOKUP($A11,WBS_계획!$A:$O,7,FALSE()),G$5<=VLOOKUP($A11,WBS_계획!$A:$O,8,FALSE())),"■","") -> ■ | H11: =IF(AND(H$5>=VLOOKUP($A11,WBS_계획!$A:$O,7,FALSE()),H$5<=VLOOKUP($A11,WBS_계획!$A:$O,8,FALSE())),"■","") -> ■ | I11: =IF(AND(I$5>=VLOOKUP($A11,WBS_계획!$A:$O,7,FALSE()),I$5<=VLOOKUP($A11,WBS_계획!$A:$O,8,FALSE())),"■","") | J11: =IF(AND(J$5>=VLOOKUP($A11,WBS_계획!$A:$O,7,FALSE()),J$5<=VLOOKUP($A11,WBS_계획!$A:$O,8,FALSE())),"■","") | K11: =IF(AND(K$5>=VLOOKUP($A11,WBS_계획!$A:$O,7,FALSE()),K$5<=VLOOKUP($A11,WBS_계획!$A:$O,8,FALSE())),"■","") | L11: =IF(AND(L$5>=VLOOKUP($A11,WBS_계획!$A:$O,7,FALSE()),L$5<=VLOOKUP($A11,WBS_계획!$A:$O,8,FALSE())),"■","") | ... AC11: =IF(AND(AC$5>=VLOOKUP($A11,WBS_계획!$A:$O,7,FALSE()),AC$5<=VLOOKUP($A11,WBS_계획!$A:$O,8,FALSE())),"■","")
A12: C.4 | B12: 경유점 작성 | C12: =VLOOKUP($A12,WBS_계획!$A:$O,6,FALSE) -> 공동 | D12: =VLOOKUP($A12,WBS_계획!$A:$O,12,FALSE) -> 완료 | E12: =IF(AND(E$5>=VLOOKUP($A12,WBS_계획!$A:$O,7,FALSE()),E$5<=VLOOKUP($A12,WBS_계획!$A:$O,8,FALSE())),"■","") | F12: =IF(AND(F$5>=VLOOKUP($A12,WBS_계획!$A:$O,7,FALSE()),F$5<=VLOOKUP($A12,WBS_계획!$A:$O,8,FALSE())),"■","") | G12: =IF(AND(G$5>=VLOOKUP($A12,WBS_계획!$A:$O,7,FALSE()),G$5<=VLOOKUP($A12,WBS_계획!$A:$O,8,FALSE())),"■","") | H12: =IF(AND(H$5>=VLOOKUP($A12,WBS_계획!$A:$O,7,FALSE()),H$5<=VLOOKUP($A12,WBS_계획!$A:$O,8,FALSE())),"■","") | I12: =IF(AND(I$5>=VLOOKUP($A12,WBS_계획!$A:$O,7,FALSE()),I$5<=VLOOKUP($A12,WBS_계획!$A:$O,8,FALSE())),"■","") | J12: =IF(AND(J$5>=VLOOKUP($A12,WBS_계획!$A:$O,7,FALSE()),J$5<=VLOOKUP($A12,WBS_계획!$A:$O,8,FALSE())),"■","") -> ■ | K12: =IF(AND(K$5>=VLOOKUP($A12,WBS_계획!$A:$O,7,FALSE()),K$5<=VLOOKUP($A12,WBS_계획!$A:$O,8,FALSE())),"■","") -> ■ | L12: =IF(AND(L$5>=VLOOKUP($A12,WBS_계획!$A:$O,7,FALSE()),L$5<=VLOOKUP($A12,WBS_계획!$A:$O,8,FALSE())),"■","") -> ■ | ... AC12: =IF(AND(AC$5>=VLOOKUP($A12,WBS_계획!$A:$O,7,FALSE()),AC$5<=VLOOKUP($A12,WBS_계획!$A:$O,8,FALSE())),"■","")
A13: C.9 | B13: (신호등) SIGNAL_WAIT 판정 | C13: =VLOOKUP($A13,WBS_계획!$A:$O,6,FALSE) -> 김예은 | D13: =VLOOKUP($A13,WBS_계획!$A:$O,12,FALSE) -> 완료 | E13: =IF(AND(E$5>=VLOOKUP($A13,WBS_계획!$A:$O,7,FALSE()),E$5<=VLOOKUP($A13,WBS_계획!$A:$O,8,FALSE())),"■","") | F13: =IF(AND(F$5>=VLOOKUP($A13,WBS_계획!$A:$O,7,FALSE()),F$5<=VLOOKUP($A13,WBS_계획!$A:$O,8,FALSE())),"■","") | G13: =IF(AND(G$5>=VLOOKUP($A13,WBS_계획!$A:$O,7,FALSE()),G$5<=VLOOKUP($A13,WBS_계획!$A:$O,8,FALSE())),"■","") | H13: =IF(AND(H$5>=VLOOKUP($A13,WBS_계획!$A:$O,7,FALSE()),H$5<=VLOOKUP($A13,WBS_계획!$A:$O,8,FALSE())),"■","") | I13: =IF(AND(I$5>=VLOOKUP($A13,WBS_계획!$A:$O,7,FALSE()),I$5<=VLOOKUP($A13,WBS_계획!$A:$O,8,FALSE())),"■","") | J13: =IF(AND(J$5>=VLOOKUP($A13,WBS_계획!$A:$O,7,FALSE()),J$5<=VLOOKUP($A13,WBS_계획!$A:$O,8,FALSE())),"■","") -> ■ | K13: =IF(AND(K$5>=VLOOKUP($A13,WBS_계획!$A:$O,7,FALSE()),K$5<=VLOOKUP($A13,WBS_계획!$A:$O,8,FALSE())),"■","") -> ■ | L13: =IF(AND(L$5>=VLOOKUP($A13,WBS_계획!$A:$O,7,FALSE()),L$5<=VLOOKUP($A13,WBS_계획!$A:$O,8,FALSE())),"■","") -> ■ | ... AC13: =IF(AND(AC$5>=VLOOKUP($A13,WBS_계획!$A:$O,7,FALSE()),AC$5<=VLOOKUP($A13,WBS_계획!$A:$O,8,FALSE())),"■","")
A14: C.10 | B14: (가속구간) ACCEL_ZONE 판정 및 속도 제어 | C14: =VLOOKUP($A14,WBS_계획!$A:$O,6,FALSE) -> 김예은 | D14: =VLOOKUP($A14,WBS_계획!$A:$O,12,FALSE) -> 완료 | E14: =IF(AND(E$5>=VLOOKUP($A14,WBS_계획!$A:$O,7,FALSE()),E$5<=VLOOKUP($A14,WBS_계획!$A:$O,8,FALSE())),"■","") | F14: =IF(AND(F$5>=VLOOKUP($A14,WBS_계획!$A:$O,7,FALSE()),F$5<=VLOOKUP($A14,WBS_계획!$A:$O,8,FALSE())),"■","") | G14: =IF(AND(G$5>=VLOOKUP($A14,WBS_계획!$A:$O,7,FALSE()),G$5<=VLOOKUP($A14,WBS_계획!$A:$O,8,FALSE())),"■","") | H14: =IF(AND(H$5>=VLOOKUP($A14,WBS_계획!$A:$O,7,FALSE()),H$5<=VLOOKUP($A14,WBS_계획!$A:$O,8,FALSE())),"■","") | I14: =IF(AND(I$5>=VLOOKUP($A14,WBS_계획!$A:$O,7,FALSE()),I$5<=VLOOKUP($A14,WBS_계획!$A:$O,8,FALSE())),"■","") | J14: =IF(AND(J$5>=VLOOKUP($A14,WBS_계획!$A:$O,7,FALSE()),J$5<=VLOOKUP($A14,WBS_계획!$A:$O,8,FALSE())),"■","") -> ■ | K14: =IF(AND(K$5>=VLOOKUP($A14,WBS_계획!$A:$O,7,FALSE()),K$5<=VLOOKUP($A14,WBS_계획!$A:$O,8,FALSE())),"■","") -> ■ | L14: =IF(AND(L$5>=VLOOKUP($A14,WBS_계획!$A:$O,7,FALSE()),L$5<=VLOOKUP($A14,WBS_계획!$A:$O,8,FALSE())),"■","") -> ■ | ... AC14: =IF(AND(AC$5>=VLOOKUP($A14,WBS_계획!$A:$O,7,FALSE()),AC$5<=VLOOKUP($A14,WBS_계획!$A:$O,8,FALSE())),"■","")
A15: D.7 | B15: HSV 색상 기반 신호/표지판 인식 | C15: =VLOOKUP($A15,WBS_계획!$A:$O,6,FALSE) -> 김예은 | D15: =VLOOKUP($A15,WBS_계획!$A:$O,12,FALSE) -> 완료 | E15: =IF(AND(E$5>=VLOOKUP($A15,WBS_계획!$A:$O,7,FALSE()),E$5<=VLOOKUP($A15,WBS_계획!$A:$O,8,FALSE())),"■","") | F15: =IF(AND(F$5>=VLOOKUP($A15,WBS_계획!$A:$O,7,FALSE()),F$5<=VLOOKUP($A15,WBS_계획!$A:$O,8,FALSE())),"■","") | G15: =IF(AND(G$5>=VLOOKUP($A15,WBS_계획!$A:$O,7,FALSE()),G$5<=VLOOKUP($A15,WBS_계획!$A:$O,8,FALSE())),"■","") | H15: =IF(AND(H$5>=VLOOKUP($A15,WBS_계획!$A:$O,7,FALSE()),H$5<=VLOOKUP($A15,WBS_계획!$A:$O,8,FALSE())),"■","") | I15: =IF(AND(I$5>=VLOOKUP($A15,WBS_계획!$A:$O,7,FALSE()),I$5<=VLOOKUP($A15,WBS_계획!$A:$O,8,FALSE())),"■","") | J15: =IF(AND(J$5>=VLOOKUP($A15,WBS_계획!$A:$O,7,FALSE()),J$5<=VLOOKUP($A15,WBS_계획!$A:$O,8,FALSE())),"■","") -> ■ | K15: =IF(AND(K$5>=VLOOKUP($A15,WBS_계획!$A:$O,7,FALSE()),K$5<=VLOOKUP($A15,WBS_계획!$A:$O,8,FALSE())),"■","") -> ■ | L15: =IF(AND(L$5>=VLOOKUP($A15,WBS_계획!$A:$O,7,FALSE()),L$5<=VLOOKUP($A15,WBS_계획!$A:$O,8,FALSE())),"■","") -> ■ | ... AC15: =IF(AND(AC$5>=VLOOKUP($A15,WBS_계획!$A:$O,7,FALSE()),AC$5<=VLOOKUP($A15,WBS_계획!$A:$O,8,FALSE())),"■","")
A16: E.5 | B16: 신호등 코스 상태 | C16: =VLOOKUP($A16,WBS_계획!$A:$O,6,FALSE) -> 김예은 | D16: =VLOOKUP($A16,WBS_계획!$A:$O,12,FALSE) -> 완료 | E16: =IF(AND(E$5>=VLOOKUP($A16,WBS_계획!$A:$O,7,FALSE()),E$5<=VLOOKUP($A16,WBS_계획!$A:$O,8,FALSE())),"■","") | F16: =IF(AND(F$5>=VLOOKUP($A16,WBS_계획!$A:$O,7,FALSE()),F$5<=VLOOKUP($A16,WBS_계획!$A:$O,8,FALSE())),"■","") | G16: =IF(AND(G$5>=VLOOKUP($A16,WBS_계획!$A:$O,7,FALSE()),G$5<=VLOOKUP($A16,WBS_계획!$A:$O,8,FALSE())),"■","") | H16: =IF(AND(H$5>=VLOOKUP($A16,WBS_계획!$A:$O,7,FALSE()),H$5<=VLOOKUP($A16,WBS_계획!$A:$O,8,FALSE())),"■","") | I16: =IF(AND(I$5>=VLOOKUP($A16,WBS_계획!$A:$O,7,FALSE()),I$5<=VLOOKUP($A16,WBS_계획!$A:$O,8,FALSE())),"■","") | J16: =IF(AND(J$5>=VLOOKUP($A16,WBS_계획!$A:$O,7,FALSE()),J$5<=VLOOKUP($A16,WBS_계획!$A:$O,8,FALSE())),"■","") -> ■ | K16: =IF(AND(K$5>=VLOOKUP($A16,WBS_계획!$A:$O,7,FALSE()),K$5<=VLOOKUP($A16,WBS_계획!$A:$O,8,FALSE())),"■","") -> ■ | L16: =IF(AND(L$5>=VLOOKUP($A16,WBS_계획!$A:$O,7,FALSE()),L$5<=VLOOKUP($A16,WBS_계획!$A:$O,8,FALSE())),"■","") -> ■ | ... AC16: =IF(AND(AC$5>=VLOOKUP($A16,WBS_계획!$A:$O,7,FALSE()),AC$5<=VLOOKUP($A16,WBS_계획!$A:$O,8,FALSE())),"■","")
A17: E.6 | B17: 가속코스 상태 | C17: =VLOOKUP($A17,WBS_계획!$A:$O,6,FALSE) -> 김예은 | D17: =VLOOKUP($A17,WBS_계획!$A:$O,12,FALSE) -> 완료 | E17: =IF(AND(E$5>=VLOOKUP($A17,WBS_계획!$A:$O,7,FALSE()),E$5<=VLOOKUP($A17,WBS_계획!$A:$O,8,FALSE())),"■","") | F17: =IF(AND(F$5>=VLOOKUP($A17,WBS_계획!$A:$O,7,FALSE()),F$5<=VLOOKUP($A17,WBS_계획!$A:$O,8,FALSE())),"■","") | G17: =IF(AND(G$5>=VLOOKUP($A17,WBS_계획!$A:$O,7,FALSE()),G$5<=VLOOKUP($A17,WBS_계획!$A:$O,8,FALSE())),"■","") | H17: =IF(AND(H$5>=VLOOKUP($A17,WBS_계획!$A:$O,7,FALSE()),H$5<=VLOOKUP($A17,WBS_계획!$A:$O,8,FALSE())),"■","") | I17: =IF(AND(I$5>=VLOOKUP($A17,WBS_계획!$A:$O,7,FALSE()),I$5<=VLOOKUP($A17,WBS_계획!$A:$O,8,FALSE())),"■","") | J17: =IF(AND(J$5>=VLOOKUP($A17,WBS_계획!$A:$O,7,FALSE()),J$5<=VLOOKUP($A17,WBS_계획!$A:$O,8,FALSE())),"■","") -> ■ | K17: =IF(AND(K$5>=VLOOKUP($A17,WBS_계획!$A:$O,7,FALSE()),K$5<=VLOOKUP($A17,WBS_계획!$A:$O,8,FALSE())),"■","") -> ■ | L17: =IF(AND(L$5>=VLOOKUP($A17,WBS_계획!$A:$O,7,FALSE()),L$5<=VLOOKUP($A17,WBS_계획!$A:$O,8,FALSE())),"■","") -> ■ | ... AC17: =IF(AND(AC$5>=VLOOKUP($A17,WBS_계획!$A:$O,7,FALSE()),AC$5<=VLOOKUP($A17,WBS_계획!$A:$O,8,FALSE())),"■","")
... A45: F.1 | B45: 전체 Launch 파일 통합 | C45: =VLOOKUP($A45,WBS_계획!$A:$O,6,FALSE) -> 공동 | D45: =VLOOKUP($A45,WBS_계획!$A:$O,12,FALSE) -> 미착수 | E45: =IF(AND(E$5>=VLOOKUP($A45,WBS_계획!$A:$O,7,FALSE()),E$5<=VLOOKUP($A45,WBS_계획!$A:$O,8,FALSE())),"■","") | F45: =IF(AND(F$5>=VLOOKUP($A45,WBS_계획!$A:$O,7,FALSE()),F$5<=VLOOKUP($A45,WBS_계획!$A:$O,8,FALSE())),"■","") | G45: =IF(AND(G$5>=VLOOKUP($A45,WBS_계획!$A:$O,7,FALSE()),G$5<=VLOOKUP($A45,WBS_계획!$A:$O,8,FALSE())),"■","") | H45: =IF(AND(H$5>=VLOOKUP($A45,WBS_계획!$A:$O,7,FALSE()),H$5<=VLOOKUP($A45,WBS_계획!$A:$O,8,FALSE())),"■","") | I45: =IF(AND(I$5>=VLOOKUP($A45,WBS_계획!$A:$O,7,FALSE()),I$5<=VLOOKUP($A45,WBS_계획!$A:$O,8,FALSE())),"■","") | J45: =IF(AND(J$5>=VLOOKUP($A45,WBS_계획!$A:$O,7,FALSE()),J$5<=VLOOKUP($A45,WBS_계획!$A:$O,8,FALSE())),"■","") | K45: =IF(AND(K$5>=VLOOKUP($A45,WBS_계획!$A:$O,7,FALSE()),K$5<=VLOOKUP($A45,WBS_계획!$A:$O,8,FALSE())),"■","") | L45: =IF(AND(L$5>=VLOOKUP($A45,WBS_계획!$A:$O,7,FALSE()),L$5<=VLOOKUP($A45,WBS_계획!$A:$O,8,FALSE())),"■","") | ... AC45: =IF(AND(AC$5>=VLOOKUP($A45,WBS_계획!$A:$O,7,FALSE()),AC$5<=VLOOKUP($A45,WBS_계획!$A:$O,8,FALSE())),"■","")

Sheet WBS_요약
D2: TurtleBot3 ROS 2 WBS 대시보드
D5: 휴머노이드시스템 | 사무실 안내·보안 로봇 프로젝트 샘플
A8: 프로젝트 기본 정보
A9: 프로젝트명 | B9: TurtleBot3 ROS 2 사무실 안내·보안 로봇 | E9: 프로젝트 기간 | F9: 46223 | G9: ~ | H9: 46248
A10: 기준일 | B10: 46230 | E10: 로봇 플랫폼 | F10: TurtleBot3 Burger | I10: ROS 2 | J10: Humble
A11: 핵심 범위 | B11: 안내·순찰·정밀 파킹·안전 대응 | E11: 관리 기준 | F11: 산출물 중심 WBS | I11: 총 4주 | J11: 20 근무일
A13: 핵심 지표
A14: 총 작업 패키지 | C14: =COUNTA(WBS_계획!A7:A89) -> 83 | E14: 완료 | G14: =COUNTIF(WBS_계획!L7:L89,"완료") -> 42 | I14: 진행중 | K14: =COUNTIF(WBS_계획!L7:L89,"진행중") -> 4
A18: 미착수 | C18: =COUNTIF(WBS_계획!L7:L89,"미착수") -> 35 | E18: 전체 진척률 | G18: =IFERROR(SUM(WBS_계획!M7:M89)/COUNTA(WBS_계획!A7:A89),0) -> 0.54698795 | I18: 남은 기간 | K18: =MAX(0,MAX(WBS_계획!H7:H89)-DATE(2026,7,27)) -> 24
A22: 대분류별 작업 현황
A23: 대분류 | B23: 작업 수 | C23: 완료 수 | D23: 평균 진척률 | P23: 차트용 진척률(%)
A24: 프로젝트 관리 | B24: =COUNTIF(WBS_계획!B7:B89,A24) -> 6 | C24: =COUNTIFS(WBS_계획!B7:B89,A24,WBS_계획!L7:L89,"완료") -> 3 | D24: =IFERROR(SUMIF(WBS_계획!B7:B89,A24,WBS_계획!M7:M89)/B24,0) -> 0.58333333 | P24: =D24*100 -> 58.333333
A25: 로봇 시스템 | B25: =COUNTIF(WBS_계획!B7:B89,A25) -> 5 | C25: =COUNTIFS(WBS_계획!B7:B89,A25,WBS_계획!L7:L89,"완료") -> 4 | D25: =IFERROR(SUMIF(WBS_계획!B7:B89,A25,WBS_계획!M7:M89)/B25,0) -> 0.8 | P25: =D25*100 -> 80
A26: 지도·자율주행 | B26: =COUNTIF(WBS_계획!B7:B89,A26) -> 13 | C26: =COUNTIFS(WBS_계획!B7:B89,A26,WBS_계획!L7:L89,"완료") -> 13 | D26: =IFERROR(SUMIF(WBS_계획!B7:B89,A26,WBS_계획!M7:M89)/B26,0) -> 1 | P26: =D26*100 -> 100
A27: 센서·비전 | B27: =COUNTIF(WBS_계획!B7:B89,A27) -> 12 | C27: =COUNTIFS(WBS_계획!B7:B89,A27,WBS_계획!L7:L89,"완료") -> 11 | D27: =IFERROR(SUMIF(WBS_계획!B7:B89,A27,WBS_계획!M7:M89)/B27,0) -> 0.95833333 | P27: =D27*100 -> 95.833333
A28: 서비스 기능 | B28: =COUNTIF(WBS_계획!B7:B89,A28) -> 10 | C28: =COUNTIFS(WBS_계획!B7:B89,A28,WBS_계획!L7:L89,"완료") -> 8 | D28: =IFERROR(SUMIF(WBS_계획!B7:B89,A28,WBS_계획!M7:M89)/B28,0) -> 1 | P28: =D28*100 -> 100
A29: 시스템 통합 | B29: =COUNTIF(WBS_계획!B7:B89,A29) -> 9 | C29: =COUNTIFS(WBS_계획!B7:B89,A29,WBS_계획!L7:L89,"완료") -> 1 | D29: =IFERROR(SUMIF(WBS_계획!B7:B89,A29,WBS_계획!M7:M89)/B29,0) -> 0.11111111 | P29: =D29*100 -> 11.111111
A30: 시험·검증 | B30: =COUNTIF(WBS_계획!B7:B89,A30) -> 14 | C30: =COUNTIFS(WBS_계획!B7:B89,A30,WBS_계획!L7:L89,"완료") -> 2 | D30: =IFERROR(SUMIF(WBS_계획!B7:B89,A30,WBS_계획!M7:M89)/B30,0) -> 0.14285714 | P30: =D30*100 -> 14.285714
A31: 문서·발표 | B31: =COUNTIF(WBS_계획!B7:B89,A31) -> 14 | C31: =COUNTIFS(WBS_계획!B7:B89,A31,WBS_계획!L7:L89,"완료") -> 0 | D31: =IFERROR(SUMIF(WBS_계획!B7:B89,A31,WBS_계획!M7:M89)/B31,0) -> 0.028571429 | P31: =D31*100 -> 2.8571429

Sheet WBS_Dictionary
A1: WBS Dictionary — 핵심 작업 패키지 정의
A4: WBS ID | B4: 작업 패키지 | C4: 목적 | D4: 주요 입력 | E4: 핵심 활동 | F4: 산출물 | G4: 완료 기준 | H4: 검증 방법
A5: 1.3 | B5: 사용자·시스템 요구사항 | C5: 서비스 시나리오를 검증 가능한 요구사항으로 변환 | D5: 서비스 시나리오, 프로젝트 목표 | E5: 요구사항 ID 부여, 기능/비기능 분류, 검증 방법 연결 | F5: 요구사항 명세서, 추적표 | G5: 모든 요구사항에 ID·검증 방법·관련 WBS 등록 | H5: 팀 검토 및 기준선 승인
A6: 2.7 | B6: 오도메트리 보정 | C6: 직진·회전 누적 오차를 줄여 자율주행 기반 확보 | D6: wheel radius, wheel separation, 측정 환경 | E6: 1m 직진 10회, 90°/180° 회전 10회, 파라미터 보정 | F6: 측정 CSV, 보정 파라미터 | G6: 보정 전후 오차 통계와 최종값 기록 | H6: 실측 거리·각도 비교
A7: 3.2 | B7: SLAM 원본 지도 | C7: 사무실 공간의 기준 지도 생성 | D7: LiDAR, odom, SLAM 설정 | E7: 전체 공간 주행, 루프 클로저 확인, 지도 저장 | F7: original_map.pgm/yaml | G7: 벽·통로 형상 재현, 누락 구역 없음 | H7: RViz 검토 및 재주행
A8: 3.5 | B8: Navigation2 설정 | C8: 안정적인 목표점 이동과 장애물 회피 확보 | D8: 서비스 지도, odom, 센서 TF | E8: Planner/Controller/Costmap/BT 파라미터 튜닝 | F8: nav2_params.yaml | G8: 단일 목표점 5회 이상 성공 | H8: 목표 도착·경로·복구 로그
A9: 4.4 | B9: ArUco 검출 | C9: 도킹 마커 ID와 영상 좌표 검출 | D9: 보정된 카메라 영상, marker dictionary | E9: 검출·필터링·중심 오차 계산 | F9: aruco_detector 노드 | G9: 조명 조건별 20회 인식 결과 기록 | H9: 인식률·실패 원인 분석
A10: 4.7 | B10: PyQt 운영 GUI | C10: 로봇 상태와 임무를 운영자가 통제 | D10: Mission 상태, 센서·알람 토픽 | E10: 임무 시작/취소, 상태 표시, 로그·알람 화면 구현 | F10: 운영 GUI | G10: 주요 상태와 알람이 실시간 표시 | H10: 시나리오 기반 GUI 시험
A11: 5.1 | B11: Mission Manager | C11: 서비스 전체 상태와 오류 흐름 관리 | D11: GUI 명령, Nav2 Action, 센서 이벤트 | E11: IDLE/GUIDE/PATROL/RETURN/DOCKING/ERROR 상태 전환 | F11: mission_manager 노드 | G11: 시작·취소·오류·복귀 전환 완성 | H11: 상태 전이 시험
A12: 5.6 | B12: 이상 감지·증거 저장 | C12: 순찰 중 이상 상황의 재현 가능한 기록 확보 | D12: 센서값, 카메라, 로봇 위치 | E12: 필터·지속시간 판단, 사진 캡처, JSON/CSV 기록 | F12: 이벤트 JSON, 사진, 로그 | G12: 시간·위치·종류·센서값·파일 경로 저장 | H12: 정상/이상 입력 시험
A13: 6.2 | B13: ArUco 정밀 파킹 | C13: Nav2 이후 최종 위치·각도를 정밀 보정 | D13: ArUco pose, cmd_vel, 안전 거리 | E13: 탐색, 정렬, 저속 접근, 재시도·후퇴 | F13: 도킹 컨트롤러 | G13: 10회 성공률과 최종 오차 기록 | H13: 도킹 반복 시험
A14: 6.4 | B14: Wi-Fi 단절 대응 | C14: 원격 통신 상실 시 위험 동작 방지 | D14: 네트워크 상태, Mission 상태 | E14: 단절 감지, 정지/복귀 정책, 로컬 임무 유지 | F14: 통신 단절 정책과 노드 | G14: 단절 5회 모두 정의된 안전 동작 | H14: Wi-Fi 강제 해제 시험
A15: 7.5 | B15: 주간 안내 10회 시험 | C15: 안내 서비스의 반복 재현성 검증 | D15: 통합 시스템, 안내 경로 | E15: 호출·목적지 이동·도착 안내·복귀 반복 | F15: 안내 시험 결과 | G15: 10회 성공률과 실패 원인 기록 | H15: 체크리스트·로그·영상
A16: 8.5 | B16: README·설치·실행 매뉴얼 | C16: 다른 PC에서 시스템을 재현할 수 있게 함 | D16: 최종 코드, 패키지 의존성, 설정 파일 | E16: 설치·빌드·실행·문제 해결 절차 작성 | F16: README, 설치/실행 매뉴얼 | G16: 신규 환경에서 문서만으로 실행 성공 | H16: 클린 환경 재현 시험

Sheet 4주_일정
A1: TurtleBot3 ROS 2 프로젝트 4주 실행 일정
A4: 주차 | B4: 기간 | C4: 주간 목표 | D4: 핵심 작업 | E4: 주요 산출물 | F4: 마일스톤 | G4: 종료 조건 | H4: 주 책임
A5: 1주차 | B5: 2026-07-20 ~ 2026-07-24 | C5: 범위 확정과 기본 시스템 구동 | D5: 프로젝트 헌장·요구사항·GitHub·ROS 2 작업공간·Bringup·센서 연결·오도메트리 1차 측정 | E5: 요구사항 명세, Bringup 로그, 센서 연결표 | F5: 범위 기준선 승인 | G5: TurtleBot3 기본 토픽과 센서 데이터가 정상 출력 | H5: PM/요구사항
A6: 2주차 | B6: 2026-07-27 ~ 2026-07-31 | C6: 핵심 기술 개별 검증 | D6: SLAM 지도·AMCL·Navigation2·외부 센서 3종·카메라 보정·ArUco 검출·경유점 작성 | E6: 지도 파일, nav2 설정, 센서/비전 노드 | F6: 핵심 기술 검증 완료 | G6: 지도 기반 단일 목표 이동과 ArUco 인식 성공 | H6: Navigation/제어
A7: 3주차 | B7: 2026-08-03 ~ 2026-08-07 | C7: 서비스 통합 | D7: Mission Manager·안내·순찰·GUI·상태 표시·ArUco 파킹·전체 Launch·통신 단절 대응 | E7: 통합 Launch, 안내/순찰 시나리오, GUI | F7: 전체 흐름 1회 성공 | G7: 전원 인가부터 임무 종료·복귀까지 동작 | H7: 서비스/GUI
A8: 4주차 | B8: 2026-08-10 ~ 2026-08-14 | C8: 시험·안정화·문서화 | D8: 주행 성능·시나리오 10회·통신/노드 장애·전원 재인가·시험 결과서·README·영상·발표 | E8: 시험 결과서, 매뉴얼, 시연 영상, Release | F8: 최종 인수 시험 | G8: 필수 요구사항 통과와 재현 가능한 배포본 완성 | H8: 시스템/시험
